Workbook
Name Acronym: Instructions!$E$33
Name COFINPERCENT: Instructions!$E$35
Name CofinRate: 'Proposal Budget'!$J$6
Name ColumnForWPNumber: Referential!$B$15
Name CurrentFileName: Referential!$B$6
Name CurrentVersion: Referential!$D$1
Name EMP_OTHER: Instructions!$C$49
Name EMP_TYPE1: Instructions!$C$45
Name EMP_TYPE2: Instructions!$C$46
Name EMP_TYPE3: Instructions!$C$47
Name EMP_TYPE4: Instructions!$C$48
Name equipment: 'Depreciation Costs'!$A$3:$L$210
Name EURequestedAmount: 'Proposal Budget'!$J$7
Name FILESTATUS: Referential!$B$17
Name LastIDBeneficiaire: Referential!$B$7
Name LastIDWorkPackages: Referential!$B$8
Name ListOfCountries: 'Country List'!$B$2:$B$249
Name MAXSUB: Instructions!$E$34
Name MFF: Referential!$B$18
Name MyRequetedEUContribution: Referential!$B$13
Name NbrColForWP: Referential!$B$11
Name PRORATA: Referential!$B$14
Name ProtectionMode: Referential!$B$16
Name SheetBEBenCell: Referential!$B$10
Name SheetBEBenNumCell: Referential!$B$9
Name StatusBudget: 'BE-WP Overview'!$D$4
Name TotalBudget: Referential!$B$12

Sheet Instructions
A1: XXXX | B1: XXXX | C1: =CurrentVersion -> [ Version LUMP SUM II - ERASMUS - v4.4_001, of 04/10/2023 10:55 ] | F1: XXXX | G1: XXXX | H1: XXXX | I1: XXXX
C2: ANNEX 1 to Part B Detailed Estimation of Costs for Lump Sums
B4: Instructions
B6: 1 | C6: This workbook for Lump Sum calculation must be uploaded in the Submission system as a mandatory document in annex to the application. Please note that if you do not upload the fully completed Excel workbook as an annex, the application cannot be submitted (the system will not allow you to submit).
B7: 2 | C7: According to the Lump sum scheme, the lump sum for a Work Package (WP) will normally be paid only when the entire Work Package has been completed. Please take this into consideration while structuring your proposal. Work Packages should be designed in a way that enables the evaluator to clearly identify whether the action has been completed.
B8: 3 | C8: We recommend using Excel 2010 or more recent.
B9: 4 | C9: The only currency used in this worksheet is EURO.
B10: 5 | C10: The first thing you need to do is to set the relevant Maximum Grant Amount (in row 34 of this sheet), and the maximum co-financing rate (in row 35, both in column E) applicable for the call. This data can be found on the Portal under Topic Conditions and in the Call document.
B11: 6 | C11: You then have to fill in only the following sheets: ‘Beneficiaries List' – ‘Work Package list’ – ‘BE XXX’ (one sheet per Participating Organisation) – ‘Depreciation costs’ (if your budget includes the purchase of equipment). The final tab "Any comments" must be used to provide key information required for a full evaluation of your detailed budget (see point 18 below).
B12: 7 | C12: You first need to start filling in the sheet 'Beneficiaries list' where you are asked to enter all participants in the project including any Affiliated Entities. To add beneficiaries, please double-click on 'Add a Beneficiary'; to add an affiliated entity, please, double-click on 'Add an Affiliated Entity'. NOTE: the costs of Associated Partners cannot appear in any part of this budget.
B13: 8 | C13: Then you can fill in the sheet 'Work Packages list', where you are asked to enter all the Work Packages. To add a work package, please double-click on 'Add a Work Package'.
B14: 9 | C14: Once you have completed the ‘Beneficiaries List' and ‘Work Package list’ sheets, or each time you add or remove a beneficiary or a work-package, you must double-click on one of the “Apply changes” buttons to generate the related sheets in the Excel workbook. At this stage your spreadsheet is ready to be edited Beneficiary by Beneficiary (BE XXX) for all the workpackages concerned. You are requested to enter for each Beneficiary Spreadsheet, all the related costs of each WorkPackage.
B15: 10 | C15: You have to complete a ‘BE XXX’ sheet per Beneficiary. This sheet includes separate sections for the various costs categories for each Work Package of the project. Complete only the number of units and the cost per unit for each cost category. The total cost per cost category will be automatically calculated. If the Beneficiary does not contribute to a specific WP or cost category, then leave it blank.
B16: 11 | C16: You have to estimate the eligible costs of your proposal using the same methodology as if these costs were declared under an actual cost-based grant agreement. Make sure the budget table is consistent with the work packages described in application form part B. For additional information, please refer to the Annotated Model Grant Agreement.
C17: Annotaded Grant Agreement in Reference-documents section of Erasmus
B18: 12 | C18: In each ‘BE XXX’ sheet, for section “A. DIRECT PERSONNEL COSTS”, you have to encode your costs using the following unit: 1 unit is 1 person-month You can customize the categories of Employees that correspond to your organisation in rows 45 to 49 below.
B19: 13 | C19: In each ‘BE XXX’ sheet, for section 'C2. Equipment', use the ‘Depreciation costs’ sheet as a tool to calculate the depreciation costs to be charged for the whole duration of the project. This amount is NOT automatically transferred to the respective ‘BE XXX’ sheet. You have to add manually the depreciation costs in the dedicated section of the ‘BE XXX’ sheet. If you have several items in the ‘Depreciation costs’ sheet for one single section (same Beneficiary, same Work Package and same “Resource type”), you must add only the total of these items to the relevant cell in the ‘BE XXX’ sheet.
B20: 14 | C20: Indirect costs will be calculated automatically in each 'BE XXX' sheet.
B21: 15 | C21: The summary tables ‘BE-WP Overview’, 'Estim costs of the project’, ‘Proposal Budget’, and ‘BE-WP Person Months' will be produced automatically.
B24: 16 | C24: The amount calculated in the 'BE-WP Overview' sheet of this Excel workbook under the heading 'Max TOTAL EU Contribution' must be copied exactly into the Requested Grant Amount in the “Section 3 - Budget”, of the application form.
B25: 17 | C25: The ‘Estim costs of the project’, Proposal Budget' and ‘BE-WP person months' sheets are there for your information and will be used during evaluation of your application.
B26: 18 | C26: If you have any comment, you can use the ‘Any comments’ sheet. If you use the category 'other' in sections ‘A.1 Staff costs’ and / or 'C.3 Other goods, works and services', you should specify the breakdown of the cost, in the 'Any comments' sheet.
B27: 19 | C27: The format of this Excel workbook is .xlsm because it uses macros. Make sure you do not disable them when filling in the different sections. However, this format cannot be uploaded to the submission system for security reasons. Only XLSX format is allowed. Therefore, please save a copy as an .xlsx document to upload it to the proposal submission tool. To save this workbook as .xlsx document: - double-click on the button 'Create XLSX Document' in cell E37 of this Instructions sheet. OR - in Excel, click on “File” and then “Save as”; in the “Save as” dialog box, choose “.xlsx” from the “Save as type” dropdown list.
E28: XXXXXXXXXXXXXXXXXXXXXXXXXXX
D31: FILL IN THE VALUES BELOW BEFORE STARTING:
C32: Insert the name of your call | D32: :
C33: Insert the acronym of your project | D33: :
C34: Maximum grant amount as stipulated in the call | D34: : | E34: TYPE HERE THE MAXIMUM GRANT AMOUNT
C35: Maximum co-financing rate as stipulated in the call | D35: : | E35: TYPE HERE THE MAXIMUM CO-FINANCING RATE
B37: X X X | C37: The document which will be created with format .XLSX will be saved in the same folder where this workbook .XLSM is currently placed. | E37: Create XLSX document
E38: Double-Click to activate
A42: You can customize here the categories of Employees that correspond to your organisation (example: Senior Staff, Junior Staff, …). Please, note that this definition is common to all Work Packages for all Beneficiaries. | D42: X X X
A43: A. DIRECT PERSONNEL COSTS
B44: A1. Employees (or equivalent) person months (you can change the types based on your structure)
C45: Type 1
C46: Type 2
C47: Type 3
C48: Type 4
C49: Type 5

Sheet Beneficiaries List
A1: XXX | B1: XXXXXXXXXXXXXXXXXXXXXXXXXXXXXXXXXXXXXXXX | C1: XXXXXXXXXXXXXXX | D1: XXXX | F1: =COUNTA(A:A) -> 17 | G1: =COUNTA(A:A) -> 17
A2: =IF(J2=INT(J2),"BE "&TEXT(J2,"000"),"BE "&TEXT(INT(J2),"000")&" / AE "&TEXT((J2-INT(J2))*(10 ^ (LEN(J2)-LEN(INT(J2))-1)),"000")) -> BE 000 / AE 001 | F2: =IF(I2="D","TO BE REMOVED","Remove this "&IF(I2="B","Beneficiary","Affiliated Entity")) -> Remove this Affiliated Entity | G2: =IF(I2="D",IF(J2=INT(J2),"UNDO DELETE this Beneficiary",IF(OFFSET(I2,INT(-1*(J2-INT(J2))*(10^(LEN(J2)-LEN(INT(J2))-1))),0)="D","","UNDO DELETE this Affiliated Entity")),IF(OR(OFFSET(I2,1,0)="T",OFFSET(I2,1,0)="D"),"","Add an Affiliated Entity")) -> Add an Affiliated Entity | H2: T | J2: =OFFSET(J2,-1,0)+0.01 -> 0.01
A3: ALL ABOVE IS HIDDEN | G3: UNDO DELETE this Affiliated Entity
A4: List of Beneficiaries and Affiliated Entities | E4: 1 | F4: Actions (double-click to activate) | M4: =F1 -> 17
A5: BE NR/AE | B5: BE/TP name | C5: Acronym | D5: Country | F5: =IF(E4=1,"APPLY CHANGES","All is coherent") -> APPLY CHANGES | G5: Add a Beneficiary
A6: =IF(J6=INT(J6),"BE "&TEXT(J6,"000"),"BE "&TEXT(INT(J6),"000")&" / AE "&TEXT((J6-INT(J6))*(10 ^ (LEN(J6)-LEN(INT(J6))-1)),"000")) -> BE 001 | F6: =IF(I6="D","TO BE REMOVED","Remove this "&IF(I6="B","Beneficiary","Affiliated Entity")) -> Remove this Beneficiary | G6: =IF(I6="D",IF(J6=INT(J6),"UNDO DELETE this Beneficiary",IF(OFFSET(I6,INT(-1*(J6-INT(J6))*(10^(LEN(J6)-LEN(INT(J6))-1))),0)="D","","UNDO DELETE this Affiliated Entity")),IF(OR(OFFSET(I6,1,0)="T",OFFSET(I6,1,0)="D"),"","Add an Affiliated Entity")) -> Add an Affiliated Entity | H6: B | I6: B | J6: 1 | K6: 1
A7: =IF(J7=INT(J7),"BE "&TEXT(J7,"000"),"BE "&TEXT(INT(J7),"000")&" / AE "&TEXT((J7-INT(J7))*(10 ^ (LEN(J7)-LEN(INT(J7))-1)),"000")) -> BE 002 | F7: =IF(I7="D","TO BE REMOVED","Remove this "&IF(I7="B","Beneficiary","Affiliated Entity")) -> Remove this Beneficiary | G7: =IF(I7="D",IF(J7=INT(J7),"UNDO DELETE this Beneficiary",IF(OFFSET(I7,INT(-1*(J7-INT(J7))*(10^(LEN(J7)-LEN(INT(J7))-1))),0)="D","","UNDO DELETE this Affiliated Entity")),IF(OR(OFFSET(I7,1,0)="T",OFFSET(I7,1,0)="D"),"","Add an Affiliated Entity")) -> Add an Affiliated Entity | H7: T | I7: B | J7: 2 | K7: 2
A8: =IF(J8=INT(J8),"BE "&TEXT(J8,"000"),"BE "&TEXT(INT(J8),"000")&" / AE "&TEXT((J8-INT(J8))*(10 ^ (LEN(J8)-LEN(INT(J8))-1)),"000")) -> BE 003 | F8: =IF(I8="D","TO BE REMOVED","Remove this "&IF(I8="B","Beneficiary","Affiliated Entity")) -> Remove this Beneficiary | G8: =IF(I8="D",IF(J8=INT(J8),"UNDO DELETE this Beneficiary",IF(OFFSET(I8,INT(-1*(J8-INT(J8))*(10^(LEN(J8)-LEN(INT(J8))-1))),0)="D","","UNDO DELETE this Affiliated Entity")),IF(OR(OFFSET(I8,1,0)="T",OFFSET(I8,1,0)="D"),"","Add an Affiliated Entity")) -> Add an Affiliated Entity | H8: T | I8: B | J8: 3 | K8: 3
A9: =IF(J9=INT(J9),"BE "&TEXT(J9,"000"),"BE "&TEXT(INT(J9),"000")&" / AE "&TEXT((J9-INT(J9))*(10 ^ (LEN(J9)-LEN(INT(J9))-1)),"000")) -> BE 004 | F9: =IF(I9="D","TO BE REMOVED","Remove this "&IF(I9="B","Beneficiary","Affiliated Entity")) -> Remove this Beneficiary | G9: =IF(I9="D",IF(J9=INT(J9),"UNDO DELETE this Beneficiary",IF(OFFSET(I9,INT(-1*(J9-INT(J9))*(10^(LEN(J9)-LEN(INT(J9))-1))),0)="D","","UNDO DELETE this Affiliated Entity")),IF(OR(OFFSET(I9,1,0)="T",OFFSET(I9,1,0)="D"),"","Add an Affiliated Entity")) -> Add an Affiliated Entity | H9: T | I9: B | J9: 4 | K9: 4
A10: =IF(J10=INT(J10),"BE "&TEXT(J10,"000"),"BE "&TEXT(INT(J10),"000")&" / AE "&TEXT((J10-INT(J10))*(10 ^ (LEN(J10)-LEN(INT(J10))-1)),"000")) -> BE 005 | F10: =IF(I10="D","TO BE REMOVED","Remove this "&IF(I10="B","Beneficiary","Affiliated Entity")) -> Remove this Beneficiary | G10: =IF(I10="D",IF(J10=INT(J10),"UNDO DELETE this Beneficiary",IF(OFFSET(I10,INT(-1*(J10-INT(J10))*(10^(LEN(J10)-LEN(INT(J10))-1))),0)="D","","UNDO DELETE this Affiliated Entity")),IF(OR(OFFSET(I10,1,0)="T",OFFSET(I10,1,0)="D"),"","Add an Affiliated Entity")) -> Add an Affiliated Entity | H10: T | I10: B | J10: 5 | K10: 5
A11: =IF(J11=INT(J11),"BE "&TEXT(J11,"000"),"BE "&TEXT(INT(J11),"000")&" / AE "&TEXT((J11-INT(J11))*(10 ^ (LEN(J11)-LEN(INT(J11))-1)),"000")) -> BE 006 | F11: =IF(I11="D","TO BE REMOVED","Remove this "&IF(I11="B","Beneficiary","Affiliated Entity")) -> Remove this Beneficiary | G11: =IF(I11="D",IF(J11=INT(J11),"UNDO DELETE this Beneficiary",IF(OFFSET(I11,INT(-1*(J11-INT(J11))*(10^(LEN(J11)-LEN(INT(J11))-1))),0)="D","","UNDO DELETE this Affiliated Entity")),IF(OR(OFFSET(I11,1,0)="T",OFFSET(I11,1,0)="D"),"","Add an Affiliated Entity")) -> Add an Affiliated Entity | H11: T | I11: B | J11: 6 | K11: 6
A12: =IF(J12=INT(J12),"BE "&TEXT(J12,"000"),"BE "&TEXT(INT(J12),"000")&" / AE "&TEXT((J12-INT(J12))*(10 ^ (LEN(J12)-LEN(INT(J12))-1)),"000")) -> BE 007 | F12: =IF(I12="D","TO BE REMOVED","Remove this "&IF(I12="B","Beneficiary","Affiliated Entity")) -> Remove this Beneficiary | G12: =IF(I12="D",IF(J12=INT(J12),"UNDO DELETE this Beneficiary",IF(OFFSET(I12,INT(-1*(J12-INT(J12))*(10^(LEN(J12)-LEN(INT(J12))-1))),0)="D","","UNDO DELETE this Affiliated Entity")),IF(OR(OFFSET(I12,1,0)="T",OFFSET(I12,1,0)="D"),"","Add an Affiliated Entity")) -> Add an Affiliated Entity | H12: T | I12: B | J12: 7 | K12: 7
A13: =IF(J13=INT(J13),"BE "&TEXT(J13,"000"),"BE "&TEXT(INT(J13),"000")&" / AE "&TEXT((J13-INT(J13))*(10 ^ (LEN(J13)-LEN(INT(J13))-1)),"000")) -> BE 008 | F13: =IF(I13="D","TO BE REMOVED","Remove this "&IF(I13="B","Beneficiary","Affiliated Entity")) -> Remove this Beneficiary | G13: =IF(I13="D",IF(J13=INT(J13),"UNDO DELETE this Beneficiary",IF(OFFSET(I13,INT(-1*(J13-INT(J13))*(10^(LEN(J13)-LEN(INT(J13))-1))),0)="D","","UNDO DELETE this Affiliated Entity")),IF(OR(OFFSET(I13,1,0)="T",OFFSET(I13,1,0)="D"),"","Add an Affiliated Entity")) -> Add an Affiliated Entity | H13: T | I13: B | J13: 8 | K13: 8
A14: =IF(J14=INT(J14),"BE "&TEXT(J14,"000"),"BE "&TEXT(INT(J14),"000")&" / AE "&TEXT((J14-INT(J14))*(10 ^ (LEN(J14)-LEN(INT(J14))-1)),"000")) -> BE 009 | F14: =IF(I14="D","TO BE REMOVED","Remove this "&IF(I14="B","Beneficiary","Affiliated Entity")) -> Remove this Beneficiary | G14: =IF(I14="D",IF(J14=INT(J14),"UNDO DELETE this Beneficiary",IF(OFFSET(I14,INT(-1*(J14-INT(J14))*(10^(LEN(J14)-LEN(INT(J14))-1))),0)="D","","UNDO DELETE this Affiliated Entity")),IF(OR(OFFSET(I14,1,0)="T",OFFSET(I14,1,0)="D"),"","Add an Affiliated Entity")) -> Add an Affiliated Entity | H14: T | I14: B | J14: 9 | K14: 9
A15: =IF(J15=INT(J15),"BE "&TEXT(J15,"000"),"BE "&TEXT(INT(J15),"000")&" / AE "&TEXT((J15-INT(J15))*(10 ^ (LEN(J15)-LEN(INT(J15))-1)),"000")) -> BE 010 | F15: =IF(I15="D","TO BE REMOVED","Remove this "&IF(I15="B","Beneficiary","Affiliated Entity")) -> Remove this Beneficiary | G15: =IF(I15="D",IF(J15=INT(J15),"UNDO DELETE this Beneficiary",IF(OFFSET(I15,INT(-1*(J15-INT(J15))*(10^(LEN(J15)-LEN(INT(J15))-1))),0)="D","","UNDO DELETE this Affiliated Entity")),IF(OR(OFFSET(I15,1,0)="T",OFFSET(I15,1,0)="D"),"","Add an Affiliated Entity")) -> Add an Affiliated Entity | H15: T | I15: B | J15: 10 | K15: 10
A16: =IF(J16=INT(J16),"BE "&TEXT(J16,"000"),"BE "&TEXT(INT(J16),"000")&" / AE "&TEXT((J16-INT(J16))*(10 ^ (LEN(J16)-LEN(INT(J16))-1)),"000")) -> BE 011 | F16: =IF(I16="D","TO BE REMOVED","Remove this "&IF(I16="B","Beneficiary","Affiliated Entity")) -> Remove this Beneficiary | G16: =IF(I16="D",IF(J16=INT(J16),"UNDO DELETE this Beneficiary",IF(OFFSET(I16,INT(-1*(J16-INT(J16))*(10^(LEN(J16)-LEN(INT(J16))-1))),0)="D","","UNDO DELETE this Affiliated Entity")),IF(OR(OFFSET(I16,1,0)="T",OFFSET(I16,1,0)="D"),"","Add an Affiliated Entity")) -> Add an Affiliated Entity | H16: T | I16: B | J16: 11 | K16: 11
A17: =IF(J17=INT(J17),"BE "&TEXT(J17,"000"),"BE "&TEXT(INT(J17),"000")&" / AE "&TEXT((J17-INT(J17))*(10 ^ (LEN(J17)-LEN(INT(J17))-1)),"000")) -> BE 012 | F17: =IF(I17="D","TO BE REMOVED","Remove this "&IF(I17="B","Beneficiary","Affiliated Entity")) -> Remove this Beneficiary | G17: =IF(I17="D",IF(J17=INT(J17),"UNDO DELETE this Beneficiary",IF(OFFSET(I17,INT(-1*(J17-INT(J17))*(10^(LEN(J17)-LEN(INT(J17))-1))),0)="D","","UNDO DELETE this Affiliated Entity")),IF(OR(OFFSET(I17,1,0)="T",OFFSET(I17,1,0)="D"),"","Add an Affiliated Entity")) -> Add an Affiliated Entity | H17: T | I17: B | J17: 12 | K17: 12

Sheet Work Packages List
A1: XXX | B1: XXXXXXXXXXXXXXXXXXXXXXXXXXXXXXXXXXXXXXXX | C1: . | F1: . | G1: =COUNTA(A:A) -> 13 | H1: .
A2: ="WP "&TEXT(J2,"000") -> WP 000 | D2: =IF(I2="D","TO BE REMOVED","Remove this Work Package") -> Remove this Work Package | E2: =IF(I2="D","UNDO DELETE this Work Package","") | I2: W
A3: ALL ABOVE IS HIDDEN
A4: List of Work Packages | D4: Actions (double-click to activate) | I4: 1 | M4: =G1 -> 13
A5: WP Nbr | B5: WP Label | D5: =IF(I4=1,"APPLY CHANGES","All is coherent") -> APPLY CHANGES | E5: Add a Work Package
A6: ="WP "&TEXT(J6,"000") -> WP 001 | D6: =IF(I6="D","TO BE REMOVED","Remove this Work Package") -> Remove this Work Package | E6: =IF(I6="D","UNDO DELETE this Work Package","") | I6: W | J6: 1
A7: ="WP "&TEXT(J7,"000") -> WP 002 | D7: =IF(I7="D","TO BE REMOVED","Remove this Work Package") -> Remove this Work Package | E7: =IF(I7="D","UNDO DELETE this Work Package","") | I7: W | J7: 2
A8: ="WP "&TEXT(J8,"000") -> WP 003 | D8: =IF(I8="D","TO BE REMOVED","Remove this Work Package") -> Remove this Work Package | E8: =IF(I8="D","UNDO DELETE this Work Package","") | I8: W | J8: 3
A9: ="WP "&TEXT(J9,"000") -> WP 004 | D9: =IF(I9="D","TO BE REMOVED","Remove this Work Package") -> Remove this Work Package | E9: =IF(I9="D","UNDO DELETE this Work Package","") | I9: W | J9: 4
A10: ="WP "&TEXT(J10,"000") -> WP 005 | D10: =IF(I10="D","TO BE REMOVED","Remove this Work Package") -> Remove this Work Package | E10: =IF(I10="D","UNDO DELETE this Work Package","") | I10: W | J10: 5
A11: ="WP "&TEXT(J11,"000") -> WP 006 | D11: =IF(I11="D","TO BE REMOVED","Remove this Work Package") -> Remove this Work Package | E11: =IF(I11="D","UNDO DELETE this Work Package","") | I11: W | J11: 6
A12: ="WP "&TEXT(J12,"000") -> WP 007 | D12: =IF(I12="D","TO BE REMOVED","Remove this Work Package") -> Remove this Work Package | E12: =IF(I12="D","UNDO DELETE this Work Package","") | I12: W | J12: 7
A13: ="WP "&TEXT(J13,"000") -> WP 008 | D13: =IF(I13="D","TO BE REMOVED","Remove this Work Package") -> Remove this Work Package | E13: =IF(I13="D","UNDO DELETE this Work Package","") | I13: W | J13: 8

Sheet BE 001
A1: 8 | B1: =IF(ISERROR(MATCH("STARTWP" & TEXT(A1,"000"),A:A,0)),"N",MATCH("STARTWP" & TEXT(A1,"000"),A:A,0)) -> 247 | C1: =COUNTIF(E:E,"GT") -> 8 | D1: =IF(ISERROR(MATCH("ENDWP" & TEXT(A1,"000"),A:A,0)),"N",MATCH("ENDWP" & TEXT(A1,"000"),A:A,0)) -> 279 | F1: =COUNTA(A:A) -> 272 | H1: TBE | I1: =MATCH(H1,2:2,0) -> 21 | J1: =MATCH("BE",2:2,0) -> 18 | K1: =COUNTIF(2:2,"TP") -> 0 | N1: 1 | O1: XX | P1: XX | Q1: B. Subcontracting costs (please specify details under worksheet "Comments") | R1: XX.XXX,XX | S1: XXXXXXXXX,XX | T1: XXXXXXXXXXX,XX | U1: XXXXXXXXXXXXXX,XX
A2: =INDIRECT("'"& MID(OFFSET(A2,ROW(A$3)-ROW(A2),IF(OFFSET(A2,ROW(A$2)-ROW(A2),2)="T",0,IF(OFFSET(A2,ROW(A$2)-ROW(A2),1)="T",-1,-2))),1,6) & "'!" & ADDRESS(ROW(A2),MATCH(INDIRECT(ADDRESS(2,COLUMN(A2)+IF(OFFSET(A2,ROW(A$2)-ROW(A2),2)="T",1,IF(OFFSET(A2,ROW(A$2)-ROW(A2),1)="T",0,-1))),TRUE),INDIRECT("'"& MID(OFFSET(A2,ROW(A$3)-ROW(A2),IF(OFFSET(A2,ROW(A$2)-ROW(A2),2)="T",0,IF(OFFSET(A2,ROW(A$2)-ROW(A2),1)="T",-1,-2))),1,6) & "'!2:2",TRUE),0)-IF(OFFSET(A2,ROW(A$2)-ROW(A2),2)="T",1,IF(OFFSET(A2,ROW(A$2)-ROW(A2),1)="T",0,-1))),TRUE) -> #REF! | N2: 99 | R2: =IF(OFFSET(R2,0,1)="","TT",IF(INT(OFFSET(R2,0,1))=OFFSET(R2,0,1),"BE","TP")) -> BE | S2: 1 | T2: =IF(OFFSET(T2,0,-2)="TT","E","T") -> T | U2: TBE
A3: X | Q3: =""&IF(OFFSET(Q3,-2,-3)="C","DETAILED",INDIRECT("'Beneficiaries List'!A" & MATCH(OFFSET(Q3,-2,-3),'Beneficiaries List'!$J:$J,0),TRUE)) -> BE 001 | R3: =""&INDIRECT("'Beneficiaries List'!A" & MATCH(OFFSET(R3,-1,1),'Beneficiaries List'!$K:$K,0),TRUE) -> BE 001 | U3: =IF(U2="TBE","BE " & TEXT(INDIRECT(ADDRESS(2,MATCH(INT(OFFSET(U3,-1,-2)),2:2,0)),TRUE),"000"),"PROJECT") -> BE 001
A4: X | R4: =""&INDIRECT("'Beneficiaries List'!B" & MATCH(OFFSET(R4,-2,1),'Beneficiaries List'!$K:$K,0),TRUE)
A5: X | E5: 0 | F5: 1 | G5: 2 | H5: 3 | I5: 4 | J5: 5 | K5: 6 | L5: 7 | Q5: =""&IF(OFFSET(Q5,-4,-3)="C","CONSOLIDATION",INDIRECT("'Beneficiaries List'!B" & MATCH(OFFSET(Q5,-4,-3),'Beneficiaries List'!$J:$J,0),TRUE)) | R5: =IF(OFFSET(R5,-3,0)="TT","BE+TP TOTAL COSTS","UNITS") -> UNITS | S5: =IF(OFFSET(S5,0,-1)="UNITS","COST PER UNIT","") -> COST PER UNIT | T5: =IF(OFFSET(T5,0,-2)="UNITS",IF(OFFSET(T5,-3,-2)="BE","BENEFICIARY","AFFILIATED ENTITY") & " TOTAL COSTS","") -> BENEFICIARY TOTAL COSTS | U5: BE+AE TOTAL COSTS
A6: X | R6: 0 | S6: -1 | T6: -2
A7: X | O7: Total WORK PACKAGES: | R7: =SUMIF($E:$E,"GT",R:R) -> 0 | T7: =SUMIF($E:$E,"GT",T:T) -> 0 | U7: =IF(OFFSET(U7,ROW(U$2)-ROW(U7),0)="TT",SUMIF(INDIRECT(ADDRESS(2,COLUMN($Q7)+1) & ":" & ADDRESS(2,COLUMN(U7)-1),TRUE),"TBE",INDIRECT(ADDRESS(ROW(U7), COLUMN($Q7)+1) & ":" & ADDRESS(ROW(U7),COLUMN(U7)-1),TRUE)),IF(OFFSET(U7,ROW(U$2)-ROW(U7),0)="TBE",SUMIF(INDIRECT(ADDRESS(2,MATCH(INT(OFFSET(U7,ROW(U$2)-ROW(U7),-2)),$2:$2,0)) & ":" & ADDRESS(2,COLUMN(U7)-1),TRUE),"T",INDIRECT(ADDRESS(ROW(U7), MATCH(INT(OFFSET(U7,ROW(U$2)-ROW(U7),-2)),$2:$2,0)) & ":" & ADDRESS(ROW(U7),COLUMN(U7)-1),TRUE)),IF(OFFSET(U7,0,COLUMN($M7)-COLUMN(U7))="V",OFFSET(U7,0,-2)*OFFSET(U7,0,-1),"TOTAL"))) -> 0
A8: X
A9: =IF(ISNUMBER(OFFSET(A9,0,13)),"START",IF(AND(OFFSET(A9,0,2)=0,OFFSET(A9,0,4)="GT"),"END",""))&OFFSET(A9,0,1) -> STARTWP001 | B9: =IF(ISNUMBER(OFFSET(B9,0,12)),"WP" & TEXT(OFFSET(B9,0,12),"000"),OFFSET(B9,-1,0)) -> WP001 | N9: 1 | O9: =""&VLOOKUP(OFFSET(N9,1,0),'Work Packages List'!A:B,2,FALSE)
A10: =IF(ISNUMBER(OFFSET(A10,0,12)),"START",IF(AND(OFFSET(A10,0,2)=0,OFFSET(A10,0,4)="GT"),"END",""))&OFFSET(A10,0,1) -> WP001 | B10: =IF(ISNUMBER(OFFSET(B10,0,11)),"WP" & TEXT(OFFSET(B10,0,11),"000"),OFFSET(B10,-1,0)) -> WP001 | C10: 4 | D10: WPRow.A | H10: TTA | I10: TA | M10: T | N10: ="WP " & TEXT(OFFSET(N10,-1,0),"000") -> WP 001 | O10: A. DIRECT PERSONNEL COSTS | R10: =IF(OFFSET(R10,ROW(R$2)-ROW(R10),0)="TT","TT",IF(OFFSET(R10,0,COLUMN($M10)-COLUMN(R10))="%",ROUND(OFFSET(R10,-2,0)*0.07,0),IF(OFFSET(R10,0,COLUMN($M10)-COLUMN(R10))="V","x",SUMIF(INDIRECT(ADDRESS(MATCH("START"&OFFSET(R10,0,COLUMN($B10)-COLUMN(R10)),$A:$A,0),$C10+COLUMN($E10)+1)&":"&ADDRESS(MATCH("END"&OFFSET(R10,0,COLUMN($B10)-COLUMN(R10)),$A:$A,0),$C10+COLUMN($E10)+1),TRUE),INDIRECT(ADDRESS(ROW(R10),$C10+COLUMN($E10)),TRUE),INDIRECT(ADDRESS(MATCH("START"&OFFSET(R10,0,COLUMN($B10)-COLUMN(R10)),$A:$A,0),COLUMN(R10))&":"&ADDRESS(MATCH("END"&OFFSET(R10,0,COLUMN($B10)-COLUMN(R10)),$A:$A,0),COLUMN(R10)),TRUE))))) -> 0 | T10: =IF(OFFSET(T10,ROW(T$2)-ROW(T10),0)="TT","TT",IF(OFFSET(T10,0,COLUMN($M10)-COLUMN(T10))="%",ROUND((OFFSET(T10,-2,0)-OFFSET(T10,-21,0))*0.07,2),IF(OFFSET(T10,0,COLUMN($M10)-COLUMN(T10))="V",ROUND(OFFSET(T10,0,-2)*OFFSET(T10,0,-1),2),SUMIF(INDIRECT(ADDRESS(MATCH("START"&OFFSET(T10,0,COLUMN($B10)-COLUMN(T10)),$A:$A,0),$C10+COLUMN($E10)+1)&":"&ADDRESS(MATCH("END"&OFFSET(T10,0,COLUMN($B10)-COLUMN(T10)),$A:$A,0),$C10+COLUMN($E10)+1),TRUE),INDIRECT(ADDRESS(ROW(T10),$C10+COLUMN($E10)),TRUE),INDIRECT(ADDRESS(MATCH("START"&OFFSET(T10,0,COLUMN($B10)-COLUMN(T10)),$A:$A,0),COLUMN(T10))&":"&ADDRESS(MATCH("END"&OFFSET(T10,0,COLUMN($B10)-COLUMN(T10)),$A:$A,0),COLUMN(T10)),TRUE))))) -> 0 | U10: =IF(OFFSET(U10,ROW(U$2)-ROW(U10),0)="TT",SUMIF(INDIRECT(ADDRESS(2,COLUMN($Q10)+1) & ":" & ADDRESS(2,COLUMN(U10)-1),TRUE),"TBE",INDIRECT(ADDRESS(ROW(U10), COLUMN($Q10)+1) & ":" & ADDRESS(ROW(U10),COLUMN(U10)-1),TRUE)),IF(OFFSET(U10,ROW(U$2)-ROW(U10),0)="TBE",SUMIF(INDIRECT(ADDRESS(2,MATCH(INT(OFFSET(U10,ROW(U$2)-ROW(U10),-2)),$2:$2,0)) & ":" & ADDRESS(2,COLUMN(U10)-1),TRUE),"T",INDIRECT(ADDRESS(ROW(U10), MATCH(INT(OFFSET(U10,ROW(U$2)-ROW(U10),-2)),$2:$2,0)) & ":" & ADDRESS(ROW(U10),COLUMN(U10)-1),TRUE)),IF(OFFSET(U10,0,COLUMN($M10)-COLUMN(U10))="V",OFFSET(U10,0,-2)*OFFSET(U10,0,-1),"TOTAL"))) -> 0
A11: =IF(ISNUMBER(OFFSET(A11,0,12)),"START",IF(AND(OFFSET(A11,0,2)=0,OFFSET(A11,0,4)="GT"),"END",""))&OFFSET(A11,0,1) -> WP001 | B11: =IF(ISNUMBER(OFFSET(B11,0,11)),"WP" & TEXT(OFFSET(B11,0,11),"000"),OFFSET(B11,-1,0)) -> WP001 | C11: 6 | D11: WPRow.B | J11: TA | K11: T1 | M11: T | P11: A1. Employees (or equivalent) person months | R11: =IF(OFFSET(R11,ROW(R$2)-ROW(R11),0)="TT","TT",IF(OFFSET(R11,0,COLUMN($M11)-COLUMN(R11))="%",ROUND(OFFSET(R11,-2,0)*0.07,0),IF(OFFSET(R11,0,COLUMN($M11)-COLUMN(R11))="V","x",SUMIF(INDIRECT(ADDRESS(MATCH("START"&OFFSET(R11,0,COLUMN($B11)-COLUMN(R11)),$A:$A,0),$C11+COLUMN($E11)+1)&":"&ADDRESS(MATCH("END"&OFFSET(R11,0,COLUMN($B11)-COLUMN(R11)),$A:$A,0),$C11+COLUMN($E11)+1),TRUE),INDIRECT(ADDRESS(ROW(R11),$C11+COLUMN($E11)),TRUE),INDIRECT(ADDRESS(MATCH("START"&OFFSET(R11,0,COLUMN($B11)-COLUMN(R11)),$A:$A,0),COLUMN(R11))&":"&ADDRESS(MATCH("END"&OFFSET(R11,0,COLUMN($B11)-COLUMN(R11)),$A:$A,0),COLUMN(R11)),TRUE))))) -> 0 | T11: =IF(OFFSET(T11,ROW(T$2)-ROW(T11),0)="TT","TT",IF(OFFSET(T11,0,COLUMN($M11)-COLUMN(T11))="%",ROUND((OFFSET(T11,-2,0)-OFFSET(T11,-21,0))*0.07,2),IF(OFFSET(T11,0,COLUMN($M11)-COLUMN(T11))="V",ROUND(OFFSET(T11,0,-2)*OFFSET(T11,0,-1),2),SUMIF(INDIRECT(ADDRESS(MATCH("START"&OFFSET(T11,0,COLUMN($B11)-COLUMN(T11)),$A:$A,0),$C11+COLUMN($E11)+1)&":"&ADDRESS(MATCH("END"&OFFSET(T11,0,COLUMN($B11)-COLUMN(T11)),$A:$A,0),$C11+COLUMN($E11)+1),TRUE),INDIRECT(ADDRESS(ROW(T11),$C11+COLUMN($E11)),TRUE),INDIRECT(ADDRESS(MATCH("START"&OFFSET(T11,0,COLUMN($B11)-COLUMN(T11)),$A:$A,0),COLUMN(T11))&":"&ADDRESS(MATCH("END"&OFFSET(T11,0,COLUMN($B11)-COLUMN(T11)),$A:$A,0),COLUMN(T11)),TRUE))))) -> 0 | U11: =IF(OFFSET(U11,ROW(U$2)-ROW(U11),0)="TT",SUMIF(INDIRECT(ADDRESS(2,COLUMN($Q11)+1) & ":" & ADDRESS(2,COLUMN(U11)-1),TRUE),"TBE",INDIRECT(ADDRESS(ROW(U11), COLUMN($Q11)+1) & ":" & ADDRESS(ROW(U11),COLUMN(U11)-1),TRUE)),IF(OFFSET(U11,ROW(U$2)-ROW(U11),0)="TBE",SUMIF(INDIRECT(ADDRESS(2,MATCH(INT(OFFSET(U11,ROW(U$2)-ROW(U11),-2)),$2:$2,0)) & ":" & ADDRESS(2,COLUMN(U11)-1),TRUE),"T",INDIRECT(ADDRESS(ROW(U11), MATCH(INT(OFFSET(U11,ROW(U$2)-ROW(U11),-2)),$2:$2,0)) & ":" & ADDRESS(ROW(U11),COLUMN(U11)-1),TRUE)),IF(OFFSET(U11,0,COLUMN($M11)-COLUMN(U11))="V",OFFSET(U11,0,-2)*OFFSET(U11,0,-1),"TOTAL"))) -> 0
A12: =IF(ISNUMBER(OFFSET(A12,0,12)),"START",IF(AND(OFFSET(A12,0,2)=0,OFFSET(A12,0,4)="GT"),"END",""))&OFFSET(A12,0,1) -> WP001 | B12: =IF(ISNUMBER(OFFSET(B12,0,11)),"WP" & TEXT(OFFSET(B12,0,11),"000"),OFFSET(B12,-1,0)) -> WP001 | C12: 7 | D12: WPRow.C | L12: T1 | M12: V | Q12: =EMP_TYPE1 -> Type 1 | T12: =IF(OFFSET(T12,ROW(T$2)-ROW(T12),0)="TT","TT",IF(OFFSET(T12,0,COLUMN($M12)-COLUMN(T12))="%",ROUND((OFFSET(T12,-2,0)-OFFSET(T12,-21,0))*0.07,2),IF(OFFSET(T12,0,COLUMN($M12)-COLUMN(T12))="V",ROUND(OFFSET(T12,0,-2)*OFFSET(T12,0,-1),2),SUMIF(INDIRECT(ADDRESS(MATCH("START"&OFFSET(T12,0,COLUMN($B12)-COLUMN(T12)),$A:$A,0),$C12+COLUMN($E12)+1)&":"&ADDRESS(MATCH("END"&OFFSET(T12,0,COLUMN($B12)-COLUMN(T12)),$A:$A,0),$C12+COLUMN($E12)+1),TRUE),INDIRECT(ADDRESS(ROW(T12),$C12+COLUMN($E12)),TRUE),INDIRECT(ADDRESS(MATCH("START"&OFFSET(T12,0,COLUMN($B12)-COLUMN(T12)),$A:$A,0),COLUMN(T12))&":"&ADDRESS(MATCH("END"&OFFSET(T12,0,COLUMN($B12)-COLUMN(T12)),$A:$A,0),COLUMN(T12)),TRUE))))) -> 0 | U12: =IF(OFFSET(U12,ROW(U$2)-ROW(U12),0)="TT",SUMIF(INDIRECT(ADDRESS(2,COLUMN($Q12)+1) & ":" & ADDRESS(2,COLUMN(U12)-1),TRUE),"TBE",INDIRECT(ADDRESS(ROW(U12), COLUMN($Q12)+1) & ":" & ADDRESS(ROW(U12),COLUMN(U12)-1),TRUE)),IF(OFFSET(U12,ROW(U$2)-ROW(U12),0)="TBE",SUMIF(INDIRECT(ADDRESS(2,MATCH(INT(OFFSET(U12,ROW(U$2)-ROW(U12),-2)),$2:$2,0)) & ":" & ADDRESS(2,COLUMN(U12)-1),TRUE),"T",INDIRECT(ADDRESS(ROW(U12), MATCH(INT(OFFSET(U12,ROW(U$2)-ROW(U12),-2)),$2:$2,0)) & ":" & ADDRESS(ROW(U12),COLUMN(U12)-1),TRUE)),IF(OFFSET(U12,0,COLUMN($M12)-COLUMN(U12))="V",OFFSET(U12,0,-2)*OFFSET(U12,0,-1),"TOTAL"))) -> 0
A13: =IF(ISNUMBER(OFFSET(A13,0,12)),"START",IF(AND(OFFSET(A13,0,2)=0,OFFSET(A13,0,4)="GT"),"END",""))&OFFSET(A13,0,1) -> WP001 | B13: =IF(ISNUMBER(OFFSET(B13,0,11)),"WP" & TEXT(OFFSET(B13,0,11),"000"),OFFSET(B13,-1,0)) -> WP001 | C13: 7 | D13: WPRow.D | L13: T1 | M13: V | Q13: =EMP_TYPE2 -> Type 2 | T13: =IF(OFFSET(T13,ROW(T$2)-ROW(T13),0)="TT","TT",IF(OFFSET(T13,0,COLUMN($M13)-COLUMN(T13))="%",ROUND((OFFSET(T13,-2,0)-OFFSET(T13,-21,0))*0.07,2),IF(OFFSET(T13,0,COLUMN($M13)-COLUMN(T13))="V",ROUND(OFFSET(T13,0,-2)*OFFSET(T13,0,-1),2),SUMIF(INDIRECT(ADDRESS(MATCH("START"&OFFSET(T13,0,COLUMN($B13)-COLUMN(T13)),$A:$A,0),$C13+COLUMN($E13)+1)&":"&ADDRESS(MATCH("END"&OFFSET(T13,0,COLUMN($B13)-COLUMN(T13)),$A:$A,0),$C13+COLUMN($E13)+1),TRUE),INDIRECT(ADDRESS(ROW(T13),$C13+COLUMN($E13)),TRUE),INDIRECT(ADDRESS(MATCH("START"&OFFSET(T13,0,COLUMN($B13)-COLUMN(T13)),$A:$A,0),COLUMN(T13))&":"&ADDRESS(MATCH("END"&OFFSET(T13,0,COLUMN($B13)-COLUMN(T13)),$A:$A,0),COLUMN(T13)),TRUE))))) -> 0 | U13: =IF(OFFSET(U13,ROW(U$2)-ROW(U13),0)="TT",SUMIF(INDIRECT(ADDRESS(2,COLUMN($Q13)+1) & ":" & ADDRESS(2,COLUMN(U13)-1),TRUE),"TBE",INDIRECT(ADDRESS(ROW(U13), COLUMN($Q13)+1) & ":" & ADDRESS(ROW(U13),COLUMN(U13)-1),TRUE)),IF(OFFSET(U13,ROW(U$2)-ROW(U13),0)="TBE",SUMIF(INDIRECT(ADDRESS(2,MATCH(INT(OFFSET(U13,ROW(U$2)-ROW(U13),-2)),$2:$2,0)) & ":" & ADDRESS(2,COLUMN(U13)-1),TRUE),"T",INDIRECT(ADDRESS(ROW(U13), MATCH(INT(OFFSET(U13,ROW(U$2)-ROW(U13),-2)),$2:$2,0)) & ":" & ADDRESS(ROW(U13),COLUMN(U13)-1),TRUE)),IF(OFFSET(U13,0,COLUMN($M13)-COLUMN(U13))="V",OFFSET(U13,0,-2)*OFFSET(U13,0,-1),"TOTAL"))) -> 0
A14: =IF(ISNUMBER(OFFSET(A14,0,12)),"START",IF(AND(OFFSET(A14,0,2)=0,OFFSET(A14,0,4)="GT"),"END",""))&OFFSET(A14,0,1) -> WP001 | B14: =IF(ISNUMBER(OFFSET(B14,0,11)),"WP" & TEXT(OFFSET(B14,0,11),"000"),OFFSET(B14,-1,0)) -> WP001 | C14: 7 | D14: WPRow.E | L14: T1 | M14: V | Q14: =EMP_TYPE3 -> Type 3 | T14: =IF(OFFSET(T14,ROW(T$2)-ROW(T14),0)="TT","TT",IF(OFFSET(T14,0,COLUMN($M14)-COLUMN(T14))="%",ROUND((OFFSET(T14,-2,0)-OFFSET(T14,-21,0))*0.07,2),IF(OFFSET(T14,0,COLUMN($M14)-COLUMN(T14))="V",ROUND(OFFSET(T14,0,-2)*OFFSET(T14,0,-1),2),SUMIF(INDIRECT(ADDRESS(MATCH("START"&OFFSET(T14,0,COLUMN($B14)-COLUMN(T14)),$A:$A,0),$C14+COLUMN($E14)+1)&":"&ADDRESS(MATCH("END"&OFFSET(T14,0,COLUMN($B14)-COLUMN(T14)),$A:$A,0),$C14+COLUMN($E14)+1),TRUE),INDIRECT(ADDRESS(ROW(T14),$C14+COLUMN($E14)),TRUE),INDIRECT(ADDRESS(MATCH("START"&OFFSET(T14,0,COLUMN($B14)-COLUMN(T14)),$A:$A,0),COLUMN(T14))&":"&ADDRESS(MATCH("END"&OFFSET(T14,0,COLUMN($B14)-COLUMN(T14)),$A:$A,0),COLUMN(T14)),TRUE))))) -> 0 | U14: =IF(OFFSET(U14,ROW(U$2)-ROW(U14),0)="TT",SUMIF(INDIRECT(ADDRESS(2,COLUMN($Q14)+1) & ":" & ADDRESS(2,COLUMN(U14)-1),TRUE),"TBE",INDIRECT(ADDRESS(ROW(U14), COLUMN($Q14)+1) & ":" & ADDRESS(ROW(U14),COLUMN(U14)-1),TRUE)),IF(OFFSET(U14,ROW(U$2)-ROW(U14),0)="TBE",SUMIF(INDIRECT(ADDRESS(2,MATCH(INT(OFFSET(U14,ROW(U$2)-ROW(U14),-2)),$2:$2,0)) & ":" & ADDRESS(2,COLUMN(U14)-1),TRUE),"T",INDIRECT(ADDRESS(ROW(U14), MATCH(INT(OFFSET(U14,ROW(U$2)-ROW(U14),-2)),$2:$2,0)) & ":" & ADDRESS(ROW(U14),COLUMN(U14)-1),TRUE)),IF(OFFSET(U14,0,COLUMN($M14)-COLUMN(U14))="V",OFFSET(U14,0,-2)*OFFSET(U14,0,-1),"TOTAL"))) -> 0
A15: =IF(ISNUMBER(OFFSET(A15,0,12)),"START",IF(AND(OFFSET(A15,0,2)=0,OFFSET(A15,0,4)="GT"),"END",""))&OFFSET(A15,0,1) -> WP001 | B15: =IF(ISNUMBER(OFFSET(B15,0,11)),"WP" & TEXT(OFFSET(B15,0,11),"000"),OFFSET(B15,-1,0)) -> WP001 | C15: 7 | D15: WPRow.F | L15: T1 | M15: V | Q15: =EMP_TYPE4 -> Type 4 | T15: =IF(OFFSET(T15,ROW(T$2)-ROW(T15),0)="TT","TT",IF(OFFSET(T15,0,COLUMN($M15)-COLUMN(T15))="%",ROUND((OFFSET(T15,-2,0)-OFFSET(T15,-21,0))*0.07,2),IF(OFFSET(T15,0,COLUMN($M15)-COLUMN(T15))="V",ROUND(OFFSET(T15,0,-2)*OFFSET(T15,0,-1),2),SUMIF(INDIRECT(ADDRESS(MATCH("START"&OFFSET(T15,0,COLUMN($B15)-COLUMN(T15)),$A:$A,0),$C15+COLUMN($E15)+1)&":"&ADDRESS(MATCH("END"&OFFSET(T15,0,COLUMN($B15)-COLUMN(T15)),$A:$A,0),$C15+COLUMN($E15)+1),TRUE),INDIRECT(ADDRESS(ROW(T15),$C15+COLUMN($E15)),TRUE),INDIRECT(ADDRESS(MATCH("START"&OFFSET(T15,0,COLUMN($B15)-COLUMN(T15)),$A:$A,0),COLUMN(T15))&":"&ADDRESS(MATCH("END"&OFFSET(T15,0,COLUMN($B15)-COLUMN(T15)),$A:$A,0),COLUMN(T15)),TRUE))))) -> 0 | U15: =IF(OFFSET(U15,ROW(U$2)-ROW(U15),0)="TT",SUMIF(INDIRECT(ADDRESS(2,COLUMN($Q15)+1) & ":" & ADDRESS(2,COLUMN(U15)-1),TRUE),"TBE",INDIRECT(ADDRESS(ROW(U15), COLUMN($Q15)+1) & ":" & ADDRESS(ROW(U15),COLUMN(U15)-1),TRUE)),IF(OFFSET(U15,ROW(U$2)-ROW(U15),0)="TBE",SUMIF(INDIRECT(ADDRESS(2,MATCH(INT(OFFSET(U15,ROW(U$2)-ROW(U15),-2)),$2:$2,0)) & ":" & ADDRESS(2,COLUMN(U15)-1),TRUE),"T",INDIRECT(ADDRESS(ROW(U15), MATCH(INT(OFFSET(U15,ROW(U$2)-ROW(U15),-2)),$2:$2,0)) & ":" & ADDRESS(ROW(U15),COLUMN(U15)-1),TRUE)),IF(OFFSET(U15,0,COLUMN($M15)-COLUMN(U15))="V",OFFSET(U15,0,-2)*OFFSET(U15,0,-1),"TOTAL"))) -> 0
A16: =IF(ISNUMBER(OFFSET(A16,0,12)),"START",IF(AND(OFFSET(A16,0,2)=0,OFFSET(A16,0,4)="GT"),"END",""))&OFFSET(A16,0,1) -> WP001 | B16: =IF(ISNUMBER(OFFSET(B16,0,11)),"WP" & TEXT(OFFSET(B16,0,11),"000"),OFFSET(B16,-1,0)) -> WP001 | C16: 7 | D16: WPRow.G | L16: T1 | M16: V | Q16: =EMP_OTHER -> Type 5 | T16: =IF(OFFSET(T16,ROW(T$2)-ROW(T16),0)="TT","TT",IF(OFFSET(T16,0,COLUMN($M16)-COLUMN(T16))="%",ROUND((OFFSET(T16,-2,0)-OFFSET(T16,-21,0))*0.07,2),IF(OFFSET(T16,0,COLUMN($M16)-COLUMN(T16))="V",ROUND(OFFSET(T16,0,-2)*OFFSET(T16,0,-1),2),SUMIF(INDIRECT(ADDRESS(MATCH("START"&OFFSET(T16,0,COLUMN($B16)-COLUMN(T16)),$A:$A,0),$C16+COLUMN($E16)+1)&":"&ADDRESS(MATCH("END"&OFFSET(T16,0,COLUMN($B16)-COLUMN(T16)),$A:$A,0),$C16+COLUMN($E16)+1),TRUE),INDIRECT(ADDRESS(ROW(T16),$C16+COLUMN($E16)),TRUE),INDIRECT(ADDRESS(MATCH("START"&OFFSET(T16,0,COLUMN($B16)-COLUMN(T16)),$A:$A,0),COLUMN(T16))&":"&ADDRESS(MATCH("END"&OFFSET(T16,0,COLUMN($B16)-COLUMN(T16)),$A:$A,0),COLUMN(T16)),TRUE))))) -> 0 | U16: =IF(OFFSET(U16,ROW(U$2)-ROW(U16),0)="TT",SUMIF(INDIRECT(ADDRESS(2,COLUMN($Q16)+1) & ":" & ADDRESS(2,COLUMN(U16)-1),TRUE),"TBE",INDIRECT(ADDRESS(ROW(U16), COLUMN($Q16)+1) & ":" & ADDRESS(ROW(U16),COLUMN(U16)-1),TRUE)),IF(OFFSET(U16,ROW(U$2)-ROW(U16),0)="TBE",SUMIF(INDIRECT(ADDRESS(2,MATCH(INT(OFFSET(U16,ROW(U$2)-ROW(U16),-2)),$2:$2,0)) & ":" & ADDRESS(2,COLUMN(U16)-1),TRUE),"T",INDIRECT(ADDRESS(ROW(U16), MATCH(INT(OFFSET(U16,ROW(U$2)-ROW(U16),-2)),$2:$2,0)) & ":" & ADDRESS(ROW(U16),COLUMN(U16)-1),TRUE)),IF(OFFSET(U16,0,COLUMN($M16)-COLUMN(U16))="V",OFFSET(U16,0,-2)*OFFSET(U16,0,-1),"TOTAL"))) -> 0
A17: =IF(ISNUMBER(OFFSET(A17,0,12)),"START",IF(AND(OFFSET(A17,0,2)=0,OFFSET(A17,0,4)="GT"),"END",""))&OFFSET(A17,0,1) -> WP001 | B17: =IF(ISNUMBER(OFFSET(B17,0,11)),"WP" & TEXT(OFFSET(B17,0,11),"000"),OFFSET(B17,-1,0)) -> WP001 | C17: 6 | D17: WPRow.H | J17: TA | M17: V | P17: A.2 Natural persons under direct contract | T17: =IF(OFFSET(T17,ROW(T$2)-ROW(T17),0)="TT","TT",IF(OFFSET(T17,0,COLUMN($M17)-COLUMN(T17))="%",ROUND((OFFSET(T17,-2,0)-OFFSET(T17,-21,0))*0.07,2),IF(OFFSET(T17,0,COLUMN($M17)-COLUMN(T17))="V",ROUND(OFFSET(T17,0,-2)*OFFSET(T17,0,-1),2),SUMIF(INDIRECT(ADDRESS(MATCH("START"&OFFSET(T17,0,COLUMN($B17)-COLUMN(T17)),$A:$A,0),$C17+COLUMN($E17)+1)&":"&ADDRESS(MATCH("END"&OFFSET(T17,0,COLUMN($B17)-COLUMN(T17)),$A:$A,0),$C17+COLUMN($E17)+1),TRUE),INDIRECT(ADDRESS(ROW(T17),$C17+COLUMN($E17)),TRUE),INDIRECT(ADDRESS(MATCH("START"&OFFSET(T17,0,COLUMN($B17)-COLUMN(T17)),$A:$A,0),COLUMN(T17))&":"&ADDRESS(MATCH("END"&OFFSET(T17,0,COLUMN($B17)-COLUMN(T17)),$A:$A,0),COLUMN(T17)),TRUE))))) -> 0 | U17: =IF(OFFSET(U17,ROW(U$2)-ROW(U17),0)="TT",SUMIF(INDIRECT(ADDRESS(2,COLUMN($Q17)+1) & ":" & ADDRESS(2,COLUMN(U17)-1),TRUE),"TBE",INDIRECT(ADDRESS(ROW(U17), COLUMN($Q17)+1) & ":" & ADDRESS(ROW(U17),COLUMN(U17)-1),TRUE)),IF(OFFSET(U17,ROW(U$2)-ROW(U17),0)="TBE",SUMIF(INDIRECT(ADDRESS(2,MATCH(INT(OFFSET(U17,ROW(U$2)-ROW(U17),-2)),$2:$2,0)) & ":" & ADDRESS(2,COLUMN(U17)-1),TRUE),"T",INDIRECT(ADDRESS(ROW(U17), MATCH(INT(OFFSET(U17,ROW(U$2)-ROW(U17),-2)),$2:$2,0)) & ":" & ADDRESS(ROW(U17),COLUMN(U17)-1),TRUE)),IF(OFFSET(U17,0,COLUMN($M17)-COLUMN(U17))="V",OFFSET(U17,0,-2)*OFFSET(U17,0,-1),"TOTAL"))) -> 0
A18: =IF(ISNUMBER(OFFSET(A18,0,12)),"START",IF(AND(OFFSET(A18,0,2)=0,OFFSET(A18,0,4)="GT"),"END",""))&OFFSET(A18,0,1) -> WP001 | B18: =IF(ISNUMBER(OFFSET(B18,0,11)),"WP" & TEXT(OFFSET(B18,0,11),"000"),OFFSET(B18,-1,0)) -> WP001 | C18: 6 | D18: WPRow.I | J18: TA | M18: V | P18: A.3 Seconded persons | T18: =IF(OFFSET(T18,ROW(T$2)-ROW(T18),0)="TT","TT",IF(OFFSET(T18,0,COLUMN($M18)-COLUMN(T18))="%",ROUND((OFFSET(T18,-2,0)-OFFSET(T18,-21,0))*0.07,2),IF(OFFSET(T18,0,COLUMN($M18)-COLUMN(T18))="V",ROUND(OFFSET(T18,0,-2)*OFFSET(T18,0,-1),2),SUMIF(INDIRECT(ADDRESS(MATCH("START"&OFFSET(T18,0,COLUMN($B18)-COLUMN(T18)),$A:$A,0),$C18+COLUMN($E18)+1)&":"&ADDRESS(MATCH("END"&OFFSET(T18,0,COLUMN($B18)-COLUMN(T18)),$A:$A,0),$C18+COLUMN($E18)+1),TRUE),INDIRECT(ADDRESS(ROW(T18),$C18+COLUMN($E18)),TRUE),INDIRECT(ADDRESS(MATCH("START"&OFFSET(T18,0,COLUMN($B18)-COLUMN(T18)),$A:$A,0),COLUMN(T18))&":"&ADDRESS(MATCH("END"&OFFSET(T18,0,COLUMN($B18)-COLUMN(T18)),$A:$A,0),COLUMN(T18)),TRUE))))) -> 0 | U18: =IF(OFFSET(U18,ROW(U$2)-ROW(U18),0)="TT",SUMIF(INDIRECT(ADDRESS(2,COLUMN($Q18)+1) & ":" & ADDRESS(2,COLUMN(U18)-1),TRUE),"TBE",INDIRECT(ADDRESS(ROW(U18), COLUMN($Q18)+1) & ":" & ADDRESS(ROW(U18),COLUMN(U18)-1),TRUE)),IF(OFFSET(U18,ROW(U$2)-ROW(U18),0)="TBE",SUMIF(INDIRECT(ADDRESS(2,MATCH(INT(OFFSET(U18,ROW(U$2)-ROW(U18),-2)),$2:$2,0)) & ":" & ADDRESS(2,COLUMN(U18)-1),TRUE),"T",INDIRECT(ADDRESS(ROW(U18), MATCH(INT(OFFSET(U18,ROW(U$2)-ROW(U18),-2)),$2:$2,0)) & ":" & ADDRESS(ROW(U18),COLUMN(U18)-1),TRUE)),IF(OFFSET(U18,0,COLUMN($M18)-COLUMN(U18))="V",OFFSET(U18,0,-2)*OFFSET(U18,0,-1),"TOTAL"))) -> 0
A19: =IF(ISNUMBER(OFFSET(A19,0,12)),"START",IF(AND(OFFSET(A19,0,2)=0,OFFSET(A19,0,4)="GT"),"END",""))&OFFSET(A19,0,1) -> WP001 | B19: =IF(ISNUMBER(OFFSET(B19,0,11)),"WP" & TEXT(OFFSET(B19,0,11),"000"),OFFSET(B19,-1,0)) -> WP001 | C19: 6 | D19: WPRow.J | J19: TA | M19: V | P19: A.4 SME Owners without salary | T19: =IF(OFFSET(T19,ROW(T$2)-ROW(T19),0)="TT","TT",IF(OFFSET(T19,0,COLUMN($M19)-COLUMN(T19))="%",ROUND((OFFSET(T19,-2,0)-OFFSET(T19,-21,0))*0.07,2),IF(OFFSET(T19,0,COLUMN($M19)-COLUMN(T19))="V",ROUND(OFFSET(T19,0,-2)*OFFSET(T19,0,-1),2),SUMIF(INDIRECT(ADDRESS(MATCH("START"&OFFSET(T19,0,COLUMN($B19)-COLUMN(T19)),$A:$A,0),$C19+COLUMN($E19)+1)&":"&ADDRESS(MATCH("END"&OFFSET(T19,0,COLUMN($B19)-COLUMN(T19)),$A:$A,0),$C19+COLUMN($E19)+1),TRUE),INDIRECT(ADDRESS(ROW(T19),$C19+COLUMN($E19)),TRUE),INDIRECT(ADDRESS(MATCH("START"&OFFSET(T19,0,COLUMN($B19)-COLUMN(T19)),$A:$A,0),COLUMN(T19))&":"&ADDRESS(MATCH("END"&OFFSET(T19,0,COLUMN($B19)-COLUMN(T19)),$A:$A,0),COLUMN(T19)),TRUE))))) -> 0 | U19: =IF(OFFSET(U19,ROW(U$2)-ROW(U19),0)="TT",SUMIF(INDIRECT(ADDRESS(2,COLUMN($Q19)+1) & ":" & ADDRESS(2,COLUMN(U19)-1),TRUE),"TBE",INDIRECT(ADDRESS(ROW(U19), COLUMN($Q19)+1) & ":" & ADDRESS(ROW(U19),COLUMN(U19)-1),TRUE)),IF(OFFSET(U19,ROW(U$2)-ROW(U19),0)="TBE",SUMIF(INDIRECT(ADDRESS(2,MATCH(INT(OFFSET(U19,ROW(U$2)-ROW(U19),-2)),$2:$2,0)) & ":" & ADDRESS(2,COLUMN(U19)-1),TRUE),"T",INDIRECT(ADDRESS(ROW(U19), MATCH(INT(OFFSET(U19,ROW(U$2)-ROW(U19),-2)),$2:$2,0)) & ":" & ADDRESS(ROW(U19),COLUMN(U19)-1),TRUE)),IF(OFFSET(U19,0,COLUMN($M19)-COLUMN(U19))="V",OFFSET(U19,0,-2)*OFFSET(U19,0,-1),"TOTAL"))) -> 0
A20: =IF(ISNUMBER(OFFSET(A20,0,12)),"START",IF(AND(OFFSET(A20,0,2)=0,OFFSET(A20,0,4)="GT"),"END",""))&OFFSET(A20,0,1) -> WP001 | B20: =IF(ISNUMBER(OFFSET(B20,0,11)),"WP" & TEXT(OFFSET(B20,0,11),"000"),OFFSET(B20,-1,0)) -> WP001 | C20: 6 | D20: WPRow.K | J20: TA | M20: V | P20: A.5 Volunteers | T20: =IF(OFFSET(T20,ROW(T$2)-ROW(T20),0)="TT","TT",IF(OFFSET(T20,0,COLUMN($M20)-COLUMN(T20))="%",ROUND((OFFSET(T20,-2,0)-OFFSET(T20,-21,0))*0.07,2),IF(OFFSET(T20,0,COLUMN($M20)-COLUMN(T20))="V",ROUND(OFFSET(T20,0,-2)*OFFSET(T20,0,-1),2),SUMIF(INDIRECT(ADDRESS(MATCH("START"&OFFSET(T20,0,COLUMN($B20)-COLUMN(T20)),$A:$A,0),$C20+COLUMN($E20)+1)&":"&ADDRESS(MATCH("END"&OFFSET(T20,0,COLUMN($B20)-COLUMN(T20)),$A:$A,0),$C20+COLUMN($E20)+1),TRUE),INDIRECT(ADDRESS(ROW(T20),$C20+COLUMN($E20)),TRUE),INDIRECT(ADDRESS(MATCH("START"&OFFSET(T20,0,COLUMN($B20)-COLUMN(T20)),$A:$A,0),COLUMN(T20))&":"&ADDRESS(MATCH("END"&OFFSET(T20,0,COLUMN($B20)-COLUMN(T20)),$A:$A,0),COLUMN(T20)),TRUE))))) -> 0 | U20: =IF(OFFSET(U20,ROW(U$2)-ROW(U20),0)="TT",SUMIF(INDIRECT(ADDRESS(2,COLUMN($Q20)+1) & ":" & ADDRESS(2,COLUMN(U20)-1),TRUE),"TBE",INDIRECT(ADDRESS(ROW(U20), COLUMN($Q20)+1) & ":" & ADDRESS(ROW(U20),COLUMN(U20)-1),TRUE)),IF(OFFSET(U20,ROW(U$2)-ROW(U20),0)="TBE",SUMIF(INDIRECT(ADDRESS(2,MATCH(INT(OFFSET(U20,ROW(U$2)-ROW(U20),-2)),$2:$2,0)) & ":" & ADDRESS(2,COLUMN(U20)-1),TRUE),"T",INDIRECT(ADDRESS(ROW(U20), MATCH(INT(OFFSET(U20,ROW(U$2)-ROW(U20),-2)),$2:$2,0)) & ":" & ADDRESS(ROW(U20),COLUMN(U20)-1),TRUE)),IF(OFFSET(U20,0,COLUMN($M20)-COLUMN(U20))="V",OFFSET(U20,0,-2)*OFFSET(U20,0,-1),"TOTAL"))) -> 0
A21: =IF(ISNUMBER(OFFSET(A21,0,12)),"START",IF(AND(OFFSET(A21,0,2)=0,OFFSET(A21,0,4)="GT"),"END",""))&OFFSET(A21,0,1) -> WP001 | B21: =IF(ISNUMBER(OFFSET(B21,0,11)),"WP" & TEXT(OFFSET(B21,0,11),"000"),OFFSET(B21,-1,0)) -> WP001 | C21: 4 | D21: WPRow.L | H21: TTA | I21: TB | M21: V | O21: B. Subcontracting costs (please specify details under worksheet "Comments") | T21: =IF(OFFSET(T21,ROW(T$2)-ROW(T21),0)="TT","TT",IF(OFFSET(T21,0,COLUMN($M21)-COLUMN(T21))="%",ROUND((OFFSET(T21,-2,0)-OFFSET(T21,-21,0))*0.07,2),IF(OFFSET(T21,0,COLUMN($M21)-COLUMN(T21))="V",ROUND(OFFSET(T21,0,-2)*OFFSET(T21,0,-1),2),SUMIF(INDIRECT(ADDRESS(MATCH("START"&OFFSET(T21,0,COLUMN($B21)-COLUMN(T21)),$A:$A,0),$C21+COLUMN($E21)+1)&":"&ADDRESS(MATCH("END"&OFFSET(T21,0,COLUMN($B21)-COLUMN(T21)),$A:$A,0),$C21+COLUMN($E21)+1),TRUE),INDIRECT(ADDRESS(ROW(T21),$C21+COLUMN($E21)),TRUE),INDIRECT(ADDRESS(MATCH("START"&OFFSET(T21,0,COLUMN($B21)-COLUMN(T21)),$A:$A,0),COLUMN(T21))&":"&ADDRESS(MATCH("END"&OFFSET(T21,0,COLUMN($B21)-COLUMN(T21)),$A:$A,0),COLUMN(T21)),TRUE))))) -> 0 | U21: =IF(OFFSET(U21,ROW(U$2)-ROW(U21),0)="TT",SUMIF(INDIRECT(ADDRESS(2,COLUMN($Q21)+1) & ":" & ADDRESS(2,COLUMN(U21)-1),TRUE),"TBE",INDIRECT(ADDRESS(ROW(U21), COLUMN($Q21)+1) & ":" & ADDRESS(ROW(U21),COLUMN(U21)-1),TRUE)),IF(OFFSET(U21,ROW(U$2)-ROW(U21),0)="TBE",SUMIF(INDIRECT(ADDRESS(2,MATCH(INT(OFFSET(U21,ROW(U$2)-ROW(U21),-2)),$2:$2,0)) & ":" & ADDRESS(2,COLUMN(U21)-1),TRUE),"T",INDIRECT(ADDRESS(ROW(U21), MATCH(INT(OFFSET(U21,ROW(U$2)-ROW(U21),-2)),$2:$2,0)) & ":" & ADDRESS(ROW(U21),COLUMN(U21)-1),TRUE)),IF(OFFSET(U21,0,COLUMN($M21)-COLUMN(U21))="V",OFFSET(U21,0,-2)*OFFSET(U21,0,-1),"TOTAL"))) -> 0
A22: =IF(ISNUMBER(OFFSET(A22,0,12)),"START",IF(AND(OFFSET(A22,0,2)=0,OFFSET(A22,0,4)="GT"),"END",""))&OFFSET(A22,0,1) -> WP001 | B22: =IF(ISNUMBER(OFFSET(B22,0,11)),"WP" & TEXT(OFFSET(B22,0,11),"000"),OFFSET(B22,-1,0)) -> WP001 | C22: 4 | D22: WPRow.M | H22: TTA | I22: TC | M22: T | O22: C. Purchase costs | T22: =IF(OFFSET(T22,ROW(T$2)-ROW(T22),0)="TT","TT",IF(OFFSET(T22,0,COLUMN($M22)-COLUMN(T22))="%",ROUND((OFFSET(T22,-2,0)-OFFSET(T22,-21,0))*0.07,2),IF(OFFSET(T22,0,COLUMN($M22)-COLUMN(T22))="V",ROUND(OFFSET(T22,0,-2)*OFFSET(T22,0,-1),2),SUMIF(INDIRECT(ADDRESS(MATCH("START"&OFFSET(T22,0,COLUMN($B22)-COLUMN(T22)),$A:$A,0),$C22+COLUMN($E22)+1)&":"&ADDRESS(MATCH("END"&OFFSET(T22,0,COLUMN($B22)-COLUMN(T22)),$A:$A,0),$C22+COLUMN($E22)+1),TRUE),INDIRECT(ADDRESS(ROW(T22),$C22+COLUMN($E22)),TRUE),INDIRECT(ADDRESS(MATCH("START"&OFFSET(T22,0,COLUMN($B22)-COLUMN(T22)),$A:$A,0),COLUMN(T22))&":"&ADDRESS(MATCH("END"&OFFSET(T22,0,COLUMN($B22)-COLUMN(T22)),$A:$A,0),COLUMN(T22)),TRUE))))) -> 0 | U22: =IF(OFFSET(U22,ROW(U$2)-ROW(U22),0)="TT",SUMIF(INDIRECT(ADDRESS(2,COLUMN($Q22)+1) & ":" & ADDRESS(2,COLUMN(U22)-1),TRUE),"TBE",INDIRECT(ADDRESS(ROW(U22), COLUMN($Q22)+1) & ":" & ADDRESS(ROW(U22),COLUMN(U22)-1),TRUE)),IF(OFFSET(U22,ROW(U$2)-ROW(U22),0)="TBE",SUMIF(INDIRECT(ADDRESS(2,MATCH(INT(OFFSET(U22,ROW(U$2)-ROW(U22),-2)),$2:$2,0)) & ":" & ADDRESS(2,COLUMN(U22)-1),TRUE),"T",INDIRECT(ADDRESS(ROW(U22), MATCH(INT(OFFSET(U22,ROW(U$2)-ROW(U22),-2)),$2:$2,0)) & ":" & ADDRESS(ROW(U22),COLUMN(U22)-1),TRUE)),IF(OFFSET(U22,0,COLUMN($M22)-COLUMN(U22))="V",OFFSET(U22,0,-2)*OFFSET(U22,0,-1),"TOTAL"))) -> 0
A23: =IF(ISNUMBER(OFFSET(A23,0,12)),"START",IF(AND(OFFSET(A23,0,2)=0,OFFSET(A23,0,4)="GT"),"END",""))&OFFSET(A23,0,1) -> WP001 | B23: =IF(ISNUMBER(OFFSET(B23,0,11)),"WP" & TEXT(OFFSET(B23,0,11),"000"),OFFSET(B23,-1,0)) -> WP001 | C23: 6 | D23: WPRow.N | J23: TC | K23: T3 | M23: T | P23: C.1 Travel and subsistence per travel or day | T23: =IF(OFFSET(T23,ROW(T$2)-ROW(T23),0)="TT","TT",IF(OFFSET(T23,0,COLUMN($M23)-COLUMN(T23))="%",ROUND((OFFSET(T23,-2,0)-OFFSET(T23,-21,0))*0.07,2),IF(OFFSET(T23,0,COLUMN($M23)-COLUMN(T23))="V",ROUND(OFFSET(T23,0,-2)*OFFSET(T23,0,-1),2),SUMIF(INDIRECT(ADDRESS(MATCH("START"&OFFSET(T23,0,COLUMN($B23)-COLUMN(T23)),$A:$A,0),$C23+COLUMN($E23)+1)&":"&ADDRESS(MATCH("END"&OFFSET(T23,0,COLUMN($B23)-COLUMN(T23)),$A:$A,0),$C23+COLUMN($E23)+1),TRUE),INDIRECT(ADDRESS(ROW(T23),$C23+COLUMN($E23)),TRUE),INDIRECT(ADDRESS(MATCH("START"&OFFSET(T23,0,COLUMN($B23)-COLUMN(T23)),$A:$A,0),COLUMN(T23))&":"&ADDRESS(MATCH("END"&OFFSET(T23,0,COLUMN($B23)-COLUMN(T23)),$A:$A,0),COLUMN(T23)),TRUE))))) -> 0 | U23: =IF(OFFSET(U23,ROW(U$2)-ROW(U23),0)="TT",SUMIF(INDIRECT(ADDRESS(2,COLUMN($Q23)+1) & ":" & ADDRESS(2,COLUMN(U23)-1),TRUE),"TBE",INDIRECT(ADDRESS(ROW(U23), COLUMN($Q23)+1) & ":" & ADDRESS(ROW(U23),COLUMN(U23)-1),TRUE)),IF(OFFSET(U23,ROW(U$2)-ROW(U23),0)="TBE",SUMIF(INDIRECT(ADDRESS(2,MATCH(INT(OFFSET(U23,ROW(U$2)-ROW(U23),-2)),$2:$2,0)) & ":" & ADDRESS(2,COLUMN(U23)-1),TRUE),"T",INDIRECT(ADDRESS(ROW(U23), MATCH(INT(OFFSET(U23,ROW(U$2)-ROW(U23),-2)),$2:$2,0)) & ":" & ADDRESS(ROW(U23),COLUMN(U23)-1),TRUE)),IF(OFFSET(U23,0,COLUMN($M23)-COLUMN(U23))="V",OFFSET(U23,0,-2)*OFFSET(U23,0,-1),"TOTAL"))) -> 0
A24: =IF(ISNUMBER(OFFSET(A24,0,12)),"START",IF(AND(OFFSET(A24,0,2)=0,OFFSET(A24,0,4)="GT"),"END",""))&OFFSET(A24,0,1) -> WP001 | B24: =IF(ISNUMBER(OFFSET(B24,0,11)),"WP" & TEXT(OFFSET(B24,0,11),"000"),OFFSET(B24,-1,0)) -> WP001 | C24: 7 | D24: WPRow.O | L24: T3 | M24: V | Q24: Travel | T24: =IF(OFFSET(T24,ROW(T$2)-ROW(T24),0)="TT","TT",IF(OFFSET(T24,0,COLUMN($M24)-COLUMN(T24))="%",ROUND((OFFSET(T24,-2,0)-OFFSET(T24,-21,0))*0.07,2),IF(OFFSET(T24,0,COLUMN($M24)-COLUMN(T24))="V",ROUND(OFFSET(T24,0,-2)*OFFSET(T24,0,-1),2),SUMIF(INDIRECT(ADDRESS(MATCH("START"&OFFSET(T24,0,COLUMN($B24)-COLUMN(T24)),$A:$A,0),$C24+COLUMN($E24)+1)&":"&ADDRESS(MATCH("END"&OFFSET(T24,0,COLUMN($B24)-COLUMN(T24)),$A:$A,0),$C24+COLUMN($E24)+1),TRUE),INDIRECT(ADDRESS(ROW(T24),$C24+COLUMN($E24)),TRUE),INDIRECT(ADDRESS(MATCH("START"&OFFSET(T24,0,COLUMN($B24)-COLUMN(T24)),$A:$A,0),COLUMN(T24))&":"&ADDRESS(MATCH("END"&OFFSET(T24,0,COLUMN($B24)-COLUMN(T24)),$A:$A,0),COLUMN(T24)),TRUE))))) -> 0 | U24: =IF(OFFSET(U24,ROW(U$2)-ROW(U24),0)="TT",SUMIF(INDIRECT(ADDRESS(2,COLUMN($Q24)+1) & ":" & ADDRESS(2,COLUMN(U24)-1),TRUE),"TBE",INDIRECT(ADDRESS(ROW(U24), COLUMN($Q24)+1) & ":" & ADDRESS(ROW(U24),COLUMN(U24)-1),TRUE)),IF(OFFSET(U24,ROW(U$2)-ROW(U24),0)="TBE",SUMIF(INDIRECT(ADDRESS(2,MATCH(INT(OFFSET(U24,ROW(U$2)-ROW(U24),-2)),$2:$2,0)) & ":" & ADDRESS(2,COLUMN(U24)-1),TRUE),"T",INDIRECT(ADDRESS(ROW(U24), MATCH(INT(OFFSET(U24,ROW(U$2)-ROW(U24),-2)),$2:$2,0)) & ":" & ADDRESS(ROW(U24),COLUMN(U24)-1),TRUE)),IF(OFFSET(U24,0,COLUMN($M24)-COLUMN(U24))="V",OFFSET(U24,0,-2)*OFFSET(U24,0,-1),"TOTAL"))) -> 0
A25: =IF(ISNUMBER(OFFSET(A25,0,12)),"START",IF(AND(OFFSET(A25,0,2)=0,OFFSET(A25,0,4)="GT"),"END",""))&OFFSET(A25,0,1) -> WP001 | B25: =IF(ISNUMBER(OFFSET(B25,0,11)),"WP" & TEXT(OFFSET(B25,0,11),"000"),OFFSET(B25,-1,0)) -> WP001 | C25: 7 | D25: WPRow.P | L25: T3 | M25: V | Q25: Accommodation | T25: =IF(OFFSET(T25,ROW(T$2)-ROW(T25),0)="TT","TT",IF(OFFSET(T25,0,COLUMN($M25)-COLUMN(T25))="%",ROUND((OFFSET(T25,-2,0)-OFFSET(T25,-21,0))*0.07,2),IF(OFFSET(T25,0,COLUMN($M25)-COLUMN(T25))="V",ROUND(OFFSET(T25,0,-2)*OFFSET(T25,0,-1),2),SUMIF(INDIRECT(ADDRESS(MATCH("START"&OFFSET(T25,0,COLUMN($B25)-COLUMN(T25)),$A:$A,0),$C25+COLUMN($E25)+1)&":"&ADDRESS(MATCH("END"&OFFSET(T25,0,COLUMN($B25)-COLUMN(T25)),$A:$A,0),$C25+COLUMN($E25)+1),TRUE),INDIRECT(ADDRESS(ROW(T25),$C25+COLUMN($E25)),TRUE),INDIRECT(ADDRESS(MATCH("START"&OFFSET(T25,0,COLUMN($B25)-COLUMN(T25)),$A:$A,0),COLUMN(T25))&":"&ADDRESS(MATCH("END"&OFFSET(T25,0,COLUMN($B25)-COLUMN(T25)),$A:$A,0),COLUMN(T25)),TRUE))))) -> 0 | U25: =IF(OFFSET(U25,ROW(U$2)-ROW(U25),0)="TT",SUMIF(INDIRECT(ADDRESS(2,COLUMN($Q25)+1) & ":" & ADDRESS(2,COLUMN(U25)-1),TRUE),"TBE",INDIRECT(ADDRESS(ROW(U25), COLUMN($Q25)+1) & ":" & ADDRESS(ROW(U25),COLUMN(U25)-1),TRUE)),IF(OFFSET(U25,ROW(U$2)-ROW(U25),0)="TBE",SUMIF(INDIRECT(ADDRESS(2,MATCH(INT(OFFSET(U25,ROW(U$2)-ROW(U25),-2)),$2:$2,0)) & ":" & ADDRESS(2,COLUMN(U25)-1),TRUE),"T",INDIRECT(ADDRESS(ROW(U25), MATCH(INT(OFFSET(U25,ROW(U$2)-ROW(U25),-2)),$2:$2,0)) & ":" & ADDRESS(ROW(U25),COLUMN(U25)-1),TRUE)),IF(OFFSET(U25,0,COLUMN($M25)-COLUMN(U25))="V",OFFSET(U25,0,-2)*OFFSET(U25,0,-1),"TOTAL"))) -> 0
A26: =IF(ISNUMBER(OFFSET(A26,0,12)),"START",IF(AND(OFFSET(A26,0,2)=0,OFFSET(A26,0,4)="GT"),"END",""))&OFFSET(A26,0,1) -> WP001 | B26: =IF(ISNUMBER(OFFSET(B26,0,11)),"WP" & TEXT(OFFSET(B26,0,11),"000"),OFFSET(B26,-1,0)) -> WP001 | C26: 7 | D26: WPRow.Q | L26: T3 | M26: V | Q26: Subsistence | T26: =IF(OFFSET(T26,ROW(T$2)-ROW(T26),0)="TT","TT",IF(OFFSET(T26,0,COLUMN($M26)-COLUMN(T26))="%",ROUND((OFFSET(T26,-2,0)-OFFSET(T26,-21,0))*0.07,2),IF(OFFSET(T26,0,COLUMN($M26)-COLUMN(T26))="V",ROUND(OFFSET(T26,0,-2)*OFFSET(T26,0,-1),2),SUMIF(INDIRECT(ADDRESS(MATCH("START"&OFFSET(T26,0,COLUMN($B26)-COLUMN(T26)),$A:$A,0),$C26+COLUMN($E26)+1)&":"&ADDRESS(MATCH("END"&OFFSET(T26,0,COLUMN($B26)-COLUMN(T26)),$A:$A,0),$C26+COLUMN($E26)+1),TRUE),INDIRECT(ADDRESS(ROW(T26),$C26+COLUMN($E26)),TRUE),INDIRECT(ADDRESS(MATCH("START"&OFFSET(T26,0,COLUMN($B26)-COLUMN(T26)),$A:$A,0),COLUMN(T26))&":"&ADDRESS(MATCH("END"&OFFSET(T26,0,COLUMN($B26)-COLUMN(T26)),$A:$A,0),COLUMN(T26)),TRUE))))) -> 0 | U26: =IF(OFFSET(U26,ROW(U$2)-ROW(U26),0)="TT",SUMIF(INDIRECT(ADDRESS(2,COLUMN($Q26)+1) & ":" & ADDRESS(2,COLUMN(U26)-1),TRUE),"TBE",INDIRECT(ADDRESS(ROW(U26), COLUMN($Q26)+1) & ":" & ADDRESS(ROW(U26),COLUMN(U26)-1),TRUE)),IF(OFFSET(U26,ROW(U$2)-ROW(U26),0)="TBE",SUMIF(INDIRECT(ADDRESS(2,MATCH(INT(OFFSET(U26,ROW(U$2)-ROW(U26),-2)),$2:$2,0)) & ":" & ADDRESS(2,COLUMN(U26)-1),TRUE),"T",INDIRECT(ADDRESS(ROW(U26), MATCH(INT(OFFSET(U26,ROW(U$2)-ROW(U26),-2)),$2:$2,0)) & ":" & ADDRESS(ROW(U26),COLUMN(U26)-1),TRUE)),IF(OFFSET(U26,0,COLUMN($M26)-COLUMN(U26))="V",OFFSET(U26,0,-2)*OFFSET(U26,0,-1),"TOTAL"))) -> 0
A27: =IF(ISNUMBER(OFFSET(A27,0,12)),"START",IF(AND(OFFSET(A27,0,2)=0,OFFSET(A27,0,4)="GT"),"END",""))&OFFSET(A27,0,1) -> WP001 | B27: =IF(ISNUMBER(OFFSET(B27,0,11)),"WP" & TEXT(OFFSET(B27,0,11),"000"),OFFSET(B27,-1,0)) -> WP001 | C27: 5 | D27: WPRow.R | J27: TC | M27: V | P27: C.2 Equipment (please refer to the Depreciation Cost sheet) | T27: =IF(OFFSET(T27,ROW(T$2)-ROW(T27),0)="TT","TT",IF(OFFSET(T27,0,COLUMN($M27)-COLUMN(T27))="%",ROUND((OFFSET(T27,-2,0)-OFFSET(T27,-21,0))*0.07,2),IF(OFFSET(T27,0,COLUMN($M27)-COLUMN(T27))="V",ROUND(OFFSET(T27,0,-2)*OFFSET(T27,0,-1),2),SUMIF(INDIRECT(ADDRESS(MATCH("START"&OFFSET(T27,0,COLUMN($B27)-COLUMN(T27)),$A:$A,0),$C27+COLUMN($E27)+1)&":"&ADDRESS(MATCH("END"&OFFSET(T27,0,COLUMN($B27)-COLUMN(T27)),$A:$A,0),$C27+COLUMN($E27)+1),TRUE),INDIRECT(ADDRESS(ROW(T27),$C27+COLUMN($E27)),TRUE),INDIRECT(ADDRESS(MATCH("START"&OFFSET(T27,0,COLUMN($B27)-COLUMN(T27)),$A:$A,0),COLUMN(T27))&":"&ADDRESS(MATCH("END"&OFFSET(T27,0,COLUMN($B27)-COLUMN(T27)),$A:$A,0),COLUMN(T27)),TRUE))))) -> 0 | U27: =IF(OFFSET(U27,ROW(U$2)-ROW(U27),0)="TT",SUMIF(INDIRECT(ADDRESS(2,COLUMN($Q27)+1) & ":" & ADDRESS(2,COLUMN(U27)-1),TRUE),"TBE",INDIRECT(ADDRESS(ROW(U27), COLUMN($Q27)+1) & ":" & ADDRESS(ROW(U27),COLUMN(U27)-1),TRUE)),IF(OFFSET(U27,ROW(U$2)-ROW(U27),0)="TBE",SUMIF(INDIRECT(ADDRESS(2,MATCH(INT(OFFSET(U27,ROW(U$2)-ROW(U27),-2)),$2:$2,0)) & ":" & ADDRESS(2,COLUMN(U27)-1),TRUE),"T",INDIRECT(ADDRESS(ROW(U27), MATCH(INT(OFFSET(U27,ROW(U$2)-ROW(U27),-2)),$2:$2,0)) & ":" & ADDRESS(ROW(U27),COLUMN(U27)-1),TRUE)),IF(OFFSET(U27,0,COLUMN($M27)-COLUMN(U27))="V",OFFSET(U27,0,-2)*OFFSET(U27,0,-1),"TOTAL"))) -> 0
A28: =IF(ISNUMBER(OFFSET(A28,0,12)),"START",IF(AND(OFFSET(A28,0,2)=0,OFFSET(A28,0,4)="GT"),"END",""))&OFFSET(A28,0,1) -> WP001 | B28: =IF(ISNUMBER(OFFSET(B28,0,11)),"WP" & TEXT(OFFSET(B28,0,11),"000"),OFFSET(B28,-1,0)) -> WP001 | C28: 6 | D28: WPRow.S | J28: TC | K28: T4 | M28: T | P28: C.3 Other goods, works and services | T28: =IF(OFFSET(T28,ROW(T$2)-ROW(T28),0)="TT","TT",IF(OFFSET(T28,0,COLUMN($M28)-COLUMN(T28))="%",ROUND((OFFSET(T28,-2,0)-OFFSET(T28,-21,0))*0.07,2),IF(OFFSET(T28,0,COLUMN($M28)-COLUMN(T28))="V",ROUND(OFFSET(T28,0,-2)*OFFSET(T28,0,-1),2),SUMIF(INDIRECT(ADDRESS(MATCH("START"&OFFSET(T28,0,COLUMN($B28)-COLUMN(T28)),$A:$A,0),$C28+COLUMN($E28)+1)&":"&ADDRESS(MATCH("END"&OFFSET(T28,0,COLUMN($B28)-COLUMN(T28)),$A:$A,0),$C28+COLUMN($E28)+1),TRUE),INDIRECT(ADDRESS(ROW(T28),$C28+COLUMN($E28)),TRUE),INDIRECT(ADDRESS(MATCH("START"&OFFSET(T28,0,COLUMN($B28)-COLUMN(T28)),$A:$A,0),COLUMN(T28))&":"&ADDRESS(MATCH("END"&OFFSET(T28,0,COLUMN($B28)-COLUMN(T28)),$A:$A,0),COLUMN(T28)),TRUE))))) -> 0 | U28: =IF(OFFSET(U28,ROW(U$2)-ROW(U28),0)="TT",SUMIF(INDIRECT(ADDRESS(2,COLUMN($Q28)+1) & ":" & ADDRESS(2,COLUMN(U28)-1),TRUE),"TBE",INDIRECT(ADDRESS(ROW(U28), COLUMN($Q28)+1) & ":" & ADDRESS(ROW(U28),COLUMN(U28)-1),TRUE)),IF(OFFSET(U28,ROW(U$2)-ROW(U28),0)="TBE",SUMIF(INDIRECT(ADDRESS(2,MATCH(INT(OFFSET(U28,ROW(U$2)-ROW(U28),-2)),$2:$2,0)) & ":" & ADDRESS(2,COLUMN(U28)-1),TRUE),"T",INDIRECT(ADDRESS(ROW(U28), MATCH(INT(OFFSET(U28,ROW(U$2)-ROW(U28),-2)),$2:$2,0)) & ":" & ADDRESS(ROW(U28),COLUMN(U28)-1),TRUE)),IF(OFFSET(U28,0,COLUMN($M28)-COLUMN(U28))="V",OFFSET(U28,0,-2)*OFFSET(U28,0,-1),"TOTAL"))) -> 0
A29: =IF(ISNUMBER(OFFSET(A29,0,12)),"START",IF(AND(OFFSET(A29,0,2)=0,OFFSET(A29,0,4)="GT"),"END",""))&OFFSET(A29,0,1) -> WP001 | B29: =IF(ISNUMBER(OFFSET(B29,0,11)),"WP" & TEXT(OFFSET(B29,0,11),"000"),OFFSET(B29,-1,0)) -> WP001 | C29: 7 | D29: WPRow.T | L29: T4 | M29: V | Q29: Consumables | T29: =IF(OFFSET(T29,ROW(T$2)-ROW(T29),0)="TT","TT",IF(OFFSET(T29,0,COLUMN($M29)-COLUMN(T29))="%",ROUND((OFFSET(T29,-2,0)-OFFSET(T29,-21,0))*0.07,2),IF(OFFSET(T29,0,COLUMN($M29)-COLUMN(T29))="V",ROUND(OFFSET(T29,0,-2)*OFFSET(T29,0,-1),2),SUMIF(INDIRECT(ADDRESS(MATCH("START"&OFFSET(T29,0,COLUMN($B29)-COLUMN(T29)),$A:$A,0),$C29+COLUMN($E29)+1)&":"&ADDRESS(MATCH("END"&OFFSET(T29,0,COLUMN($B29)-COLUMN(T29)),$A:$A,0),$C29+COLUMN($E29)+1),TRUE),INDIRECT(ADDRESS(ROW(T29),$C29+COLUMN($E29)),TRUE),INDIRECT(ADDRESS(MATCH("START"&OFFSET(T29,0,COLUMN($B29)-COLUMN(T29)),$A:$A,0),COLUMN(T29))&":"&ADDRESS(MATCH("END"&OFFSET(T29,0,COLUMN($B29)-COLUMN(T29)),$A:$A,0),COLUMN(T29)),TRUE))))) -> 0 | U29: =IF(OFFSET(U29,ROW(U$2)-ROW(U29),0)="TT",SUMIF(INDIRECT(ADDRESS(2,COLUMN($Q29)+1) & ":" & ADDRESS(2,COLUMN(U29)-1),TRUE),"TBE",INDIRECT(ADDRESS(ROW(U29), COLUMN($Q29)+1) & ":" & ADDRESS(ROW(U29),COLUMN(U29)-1),TRUE)),IF(OFFSET(U29,ROW(U$2)-ROW(U29),0)="TBE",SUMIF(INDIRECT(ADDRESS(2,MATCH(INT(OFFSET(U29,ROW(U$2)-ROW(U29),-2)),$2:$2,0)) & ":" & ADDRESS(2,COLUMN(U29)-1),TRUE),"T",INDIRECT(ADDRESS(ROW(U29), MATCH(INT(OFFSET(U29,ROW(U$2)-ROW(U29),-2)),$2:$2,0)) & ":" & ADDRESS(ROW(U29),COLUMN(U29)-1),TRUE)),IF(OFFSET(U29,0,COLUMN($M29)-COLUMN(U29))="V",OFFSET(U29,0,-2)*OFFSET(U29,0,-1),"TOTAL"))) -> 0
A30: =IF(ISNUMBER(OFFSET(A30,0,12)),"START",IF(AND(OFFSET(A30,0,2)=0,OFFSET(A30,0,4)="GT"),"END",""))&OFFSET(A30,0,1) -> WP001 | B30: =IF(ISNUMBER(OFFSET(B30,0,11)),"WP" & TEXT(OFFSET(B30,0,11),"000"),OFFSET(B30,-1,0)) -> WP001 | C30: 7 | D30: WPRow.U | L30: T4 | M30: V | Q30: Services for Meetings, Seminars | T30: =IF(OFFSET(T30,ROW(T$2)-ROW(T30),0)="TT","TT",IF(OFFSET(T30,0,COLUMN($M30)-COLUMN(T30))="%",ROUND((OFFSET(T30,-2,0)-OFFSET(T30,-21,0))*0.07,2),IF(OFFSET(T30,0,COLUMN($M30)-COLUMN(T30))="V",ROUND(OFFSET(T30,0,-2)*OFFSET(T30,0,-1),2),SUMIF(INDIRECT(ADDRESS(MATCH("START"&OFFSET(T30,0,COLUMN($B30)-COLUMN(T30)),$A:$A,0),$C30+COLUMN($E30)+1)&":"&ADDRESS(MATCH("END"&OFFSET(T30,0,COLUMN($B30)-COLUMN(T30)),$A:$A,0),$C30+COLUMN($E30)+1),TRUE),INDIRECT(ADDRESS(ROW(T30),$C30+COLUMN($E30)),TRUE),INDIRECT(ADDRESS(MATCH("START"&OFFSET(T30,0,COLUMN($B30)-COLUMN(T30)),$A:$A,0),COLUMN(T30))&":"&ADDRESS(MATCH("END"&OFFSET(T30,0,COLUMN($B30)-COLUMN(T30)),$A:$A,0),COLUMN(T30)),TRUE))))) -> 0 | U30: =IF(OFFSET(U30,ROW(U$2)-ROW(U30),0)="TT",SUMIF(INDIRECT(ADDRESS(2,COLUMN($Q30)+1) & ":" & ADDRESS(2,COLUMN(U30)-1),TRUE),"TBE",INDIRECT(ADDRESS(ROW(U30), COLUMN($Q30)+1) & ":" & ADDRESS(ROW(U30),COLUMN(U30)-1),TRUE)),IF(OFFSET(U30,ROW(U$2)-ROW(U30),0)="TBE",SUMIF(INDIRECT(ADDRESS(2,MATCH(INT(OFFSET(U30,ROW(U$2)-ROW(U30),-2)),$2:$2,0)) & ":" & ADDRESS(2,COLUMN(U30)-1),TRUE),"T",INDIRECT(ADDRESS(ROW(U30), MATCH(INT(OFFSET(U30,ROW(U$2)-ROW(U30),-2)),$2:$2,0)) & ":" & ADDRESS(ROW(U30),COLUMN(U30)-1),TRUE)),IF(OFFSET(U30,0,COLUMN($M30)-COLUMN(U30))="V",OFFSET(U30,0,-2)*OFFSET(U30,0,-1),"TOTAL"))) -> 0
A31: =IF(ISNUMBER(OFFSET(A31,0,12)),"START",IF(AND(OFFSET(A31,0,2)=0,OFFSET(A31,0,4)="GT"),"END",""))&OFFSET(A31,0,1) -> WP001 | B31: =IF(ISNUMBER(OFFSET(B31,0,11)),"WP" & TEXT(OFFSET(B31,0,11),"000"),OFFSET(B31,-1,0)) -> WP001 | C31: 7 | D31: WPRow.V | L31: T4 | M31: V | Q31: Services for communication/promotion/dissemination | T31: =IF(OFFSET(T31,ROW(T$2)-ROW(T31),0)="TT","TT",IF(OFFSET(T31,0,COLUMN($M31)-COLUMN(T31))="%",ROUND((OFFSET(T31,-2,0)-OFFSET(T31,-21,0))*0.07,2),IF(OFFSET(T31,0,COLUMN($M31)-COLUMN(T31))="V",ROUND(OFFSET(T31,0,-2)*OFFSET(T31,0,-1),2),SUMIF(INDIRECT(ADDRESS(MATCH("START"&OFFSET(T31,0,COLUMN($B31)-COLUMN(T31)),$A:$A,0),$C31+COLUMN($E31)+1)&":"&ADDRESS(MATCH("END"&OFFSET(T31,0,COLUMN($B31)-COLUMN(T31)),$A:$A,0),$C31+COLUMN($E31)+1),TRUE),INDIRECT(ADDRESS(ROW(T31),$C31+COLUMN($E31)),TRUE),INDIRECT(ADDRESS(MATCH("START"&OFFSET(T31,0,COLUMN($B31)-COLUMN(T31)),$A:$A,0),COLUMN(T31))&":"&ADDRESS(MATCH("END"&OFFSET(T31,0,COLUMN($B31)-COLUMN(T31)),$A:$A,0),COLUMN(T31)),TRUE))))) -> 0 | U31: =IF(OFFSET(U31,ROW(U$2)-ROW(U31),0)="TT",SUMIF(INDIRECT(ADDRESS(2,COLUMN($Q31)+1) & ":" & ADDRESS(2,COLUMN(U31)-1),TRUE),"TBE",INDIRECT(ADDRESS(ROW(U31), COLUMN($Q31)+1) & ":" & ADDRESS(ROW(U31),COLUMN(U31)-1),TRUE)),IF(OFFSET(U31,ROW(U$2)-ROW(U31),0)="TBE",SUMIF(INDIRECT(ADDRESS(2,MATCH(INT(OFFSET(U31,ROW(U$2)-ROW(U31),-2)),$2:$2,0)) & ":" & ADDRESS(2,COLUMN(U31)-1),TRUE),"T",INDIRECT(ADDRESS(ROW(U31), MATCH(INT(OFFSET(U31,ROW(U$2)-ROW(U31),-2)),$2:$2,0)) & ":" & ADDRESS(ROW(U31),COLUMN(U31)-1),TRUE)),IF(OFFSET(U31,0,COLUMN($M31)-COLUMN(U31))="V",OFFSET(U31,0,-2)*OFFSET(U31,0,-1),"TOTAL"))) -> 0
